Traceback (most recent call last):
  File "A3.py", line 29, in <module>
    if i_qR % nproc != rank:
NameError: name 'nproc' is not defined
Traceback (most recent call last):
  File "A3.py", line 29, in <module>
    if i_qR % nproc != rank:
NameError: name 'nproc' is not defined
Traceback (most recent call last):
  File "A3.py", line 29, in <module>
    if i_qR % nproc != rank:
NameError: name 'nproc' is not defined
Traceback (most recent call last):
  File "A3.py", line 29, in <module>
    if i_qR % nproc != rank:
NameError: name 'nproc' is not defined
Traceback (most recent call last):
  File "A3.py", line 29, in <module>
    if i_qR % nproc != rank:
NameError: name 'nproc' is not defined
Traceback (most recent call last):
  File "A3.py", line 29, in <module>
    if i_qR % nproc != rank:
NameError: name 'nproc' is not defined
Traceback (most recent call last):
  File "A3.py", line 29, in <module>
    if i_qR % nproc != rank:
NameError: name 'nproc' is not defined
Traceback (most recent call last):
  File "A3.py", line 29, in <module>
    if i_qR % nproc != rank:
NameError: name 'nproc' is not defined
Traceback (most recent call last):
  File "A3.py", line 29, in <module>
    if i_qR % nproc != rank:
NameError: name 'nproc' is not defined
Traceback (most recent call last):
  File "A3.py", line 29, in <module>
    if i_qR % nproc != rank:
NameError: name 'nproc' is not defined
Traceback (most recent call last):
  File "A3.py", line 29, in <module>
    if i_qR % nproc != rank:
NameError: name 'nproc' is not defined
Traceback (most recent call last):
  File "A3.py", line 29, in <module>
    if i_qR % nproc != rank:
NameError: name 'nproc' is not defined
Traceback (most recent call last):
  File "A3.py", line 29, in <module>
    if i_qR % nproc != rank:
NameError: name 'nproc' is not defined
Traceback (most recent call last):
  File "A3.py", line 29, in <module>
    if i_qR % nproc != rank:
NameError: name 'nproc' is not defined
Traceback (most recent call last):
  File "A3.py", line 29, in <module>
    if i_qR % nproc != rank:
NameError: name 'nproc' is not defined
Traceback (most recent call last):
  File "A3.py", line 29, in <module>
    if i_qR % nproc != rank:
NameError: name 'nproc' is not defined
Traceback (most recent call last):
  File "A3.py", line 64, in <module>
    np.save("data/%s_A3s_%d.npy"%(sample,rank), A3s)
  File "/u/xo/phsun/anaconda2/lib/python2.7/site-packages/numpy/lib/npyio.py", line 398, in save
    fid = open(file, "wb")
IOError: [Errno 13] Permission denied: 'data/Al_A3s_2.npy'
Traceback (most recent call last):
  File "A3.py", line 64, in <module>
    np.save("data/%s_A3s_%d.npy"%(sample,rank), A3s)
  File "/u/xo/phsun/anaconda2/lib/python2.7/site-packages/numpy/lib/npyio.py", line 398, in save
    fid = open(file, "wb")
IOError: [Errno 13] Permission denied: 'data/Al_A3s_15.npy'
Traceback (most recent call last):
  File "A3.py", line 64, in <module>
    np.save("data/%s_A3s_%d.npy"%(sample,rank), A3s)
  File "/u/xo/phsun/anaconda2/lib/python2.7/site-packages/numpy/lib/npyio.py", line 398, in save
    fid = open(file, "wb")
IOError: [Errno 13] Permission denied: 'data/Al_A3s_11.npy'
Traceback (most recent call last):
  File "A3.py", line 64, in <module>
    np.save("data/%s_A3s_%d.npy"%(sample,rank), A3s)
  File "/u/xo/phsun/anaconda2/lib/python2.7/site-packages/numpy/lib/npyio.py", line 398, in save
    fid = open(file, "wb")
IOError: [Errno 13] Permission denied: 'data/Al_A3s_10.npy'
Traceback (most recent call last):
  File "A3.py", line 64, in <module>
    np.save("data/%s_A3s_%d.npy"%(sample,rank), A3s)
  File "/u/xo/phsun/anaconda2/lib/python2.7/site-packages/numpy/lib/npyio.py", line 398, in save
    fid = open(file, "wb")
IOError: [Errno 13] Permission denied: 'data/Al_A3s_14.npy'
Traceback (most recent call last):
  File "A3.py", line 64, in <module>
    np.save("data/%s_A3s_%d.npy"%(sample,rank), A3s)
  File "/u/xo/phsun/anaconda2/lib/python2.7/site-packages/numpy/lib/npyio.py", line 398, in save
    fid = open(file, "wb")
IOError: [Errno 13] Permission denied: 'data/Al_A3s_7.npy'
Traceback (most recent call last):
  File "A3.py", line 64, in <module>
    np.save("data/%s_A3s_%d.npy"%(sample,rank), A3s)
  File "/u/xo/phsun/anaconda2/lib/python2.7/site-packages/numpy/lib/npyio.py", line 398, in save
    fid = open(file, "wb")
IOError: [Errno 13] Permission denied: 'data/Al_A3s_6.npy'
Traceback (most recent call last):
  File "A3.py", line 64, in <module>
    np.save("data/%s_A3s_%d.npy"%(sample,rank), A3s)
  File "/u/xo/phsun/anaconda2/lib/python2.7/site-packages/numpy/lib/npyio.py", line 398, in save
    fid = open(file, "wb")
IOError: [Errno 13] Permission denied: 'data/Al_A3s_5.npy'
Traceback (most recent call last):
  File "A3.py", line 64, in <module>
    np.save("data/%s_A3s_%d.npy"%(sample,rank), A3s)
  File "/u/xo/phsun/anaconda2/lib/python2.7/site-packages/numpy/lib/npyio.py", line 398, in save
    fid = open(file, "wb")
IOError: [Errno 13] Permission denied: 'data/Al_A3s_4.npy'
Traceback (most recent call last):
  File "A3.py", line 64, in <module>
    np.save("data/%s_A3s_%d.npy"%(sample,rank), A3s)
  File "/u/xo/phsun/anaconda2/lib/python2.7/site-packages/numpy/lib/npyio.py", line 398, in save
    fid = open(file, "wb")
IOError: [Errno 13] Permission denied: 'data/Al_A3s_1.npy'
Traceback (most recent call last):
  File "A3.py", line 64, in <module>
    np.save("data/%s_A3s_%d.npy"%(sample,rank), A3s)
  File "/u/xo/phsun/anaconda2/lib/python2.7/site-packages/numpy/lib/npyio.py", line 398, in save
    fid = open(file, "wb")
IOError: [Errno 13] Permission denied: 'data/Al_A3s_8.npy'
Traceback (most recent call last):
  File "A3.py", line 64, in <module>
    np.save("data/%s_A3s_%d.npy"%(sample,rank), A3s)
  File "/u/xo/phsun/anaconda2/lib/python2.7/site-packages/numpy/lib/npyio.py", line 398, in save
    fid = open(file, "wb")
IOError: [Errno 13] Permission denied: 'data/Al_A3s_9.npy'
Traceback (most recent call last):
  File "A3.py", line 64, in <module>
    np.save("data/%s_A3s_%d.npy"%(sample,rank), A3s)
  File "/u/xo/phsun/anaconda2/lib/python2.7/site-packages/numpy/lib/npyio.py", line 398, in save
    fid = open(file, "wb")
IOError: [Errno 13] Permission denied: 'data/Al_A3s_12.npy'
Traceback (most recent call last):
  File "A3.py", line 64, in <module>
    np.save("data/%s_A3s_%d.npy"%(sample,rank), A3s)
  File "/u/xo/phsun/anaconda2/lib/python2.7/site-packages/numpy/lib/npyio.py", line 398, in save
    fid = open(file, "wb")
IOError: [Errno 13] Permission denied: 'data/Al_A3s_13.npy'
Traceback (most recent call last):
  File "A3.py", line 64, in <module>
    np.save("data/%s_A3s_%d.npy"%(sample,rank), A3s)
  File "/u/xo/phsun/anaconda2/lib/python2.7/site-packages/numpy/lib/npyio.py", line 398, in save
    fid = open(file, "wb")
IOError: [Errno 13] Permission denied: 'data/Al_A3s_3.npy'
